Workbook

Sheet Overview
A1: Task | B1: Notation | C1: Norm. Acc. | D1: Avg. Time (s) | E1: Avg. Tokens (OpenAI) | F1: Error
A2: ALL | B2: XML | C2: =AVERAGEIF(XML!E2:E151, ">0") -> 0.87025316 | D2: =AVERAGEIF(XML!$H2:$H151,"<>Error",XML!F2:F151) -> 73.699583 | E2: =AVERAGEIF(XML!$H2:$H151,"<>Error",XML!G2:G151) -> 19854.708 | F2: =COUNTIF(XML!H2:H151, "Error") -> 78
A3: ALL | B3: JSON | C3: =AVERAGEIF(JSON!E2:E151, ">0") -> 0.91377044 | D3: =AVERAGEIF(JSON!$H2:$H151,"<>Error",JSON!F2:F151) -> 25.12803 | E3: =AVERAGEIF(JSON!$H2:$H151,"<>Error",JSON!G2:G151) -> 8765.5379 | F3: =COUNTIF(JSON!H2:H151, "Error") -> 18
A4: ALL | B4: LION | C4: =AVERAGEIF(LION!E2:E151, ">0") -> 0.91300967 | D4: =AVERAGEIF(LION!$H2:$H151,"<>Error",LION!F2:F151) -> 16.373931 | E4: =AVERAGEIF(LION!$H2:$H151,"<>Error",LION!G2:G151) -> 7964.0897 | F4: =COUNTIF(LION!H2:H151, "Error") -> 5
A5: ALL | B5: AGENTIC | C5: =AVERAGEIF(Agentic!E2:E151, ">0") -> 0.98420106 | D5: =AVERAGEIF(Agentic!$H23:$H151,"<>Error",Agentic!F2:F151) -> 145.776 | E5: =AVERAGEIF(Agentic!$H2:$H151,"<>Error",Agentic!G2:G151) -> 53132.16 | F5: =COUNTIF(Agentic!H2:H151, "Error") -> 0

Sheet XML
A1: Task ID | B1: Task Title | C1: Run # | D1: Accuracy | E1: Norm. Acc. | F1: Time (s) | G1: Tokens (OpenAI) | H1: Error
A2: task_01 | B2: Return Processing in Online Retail | C2: 1 | D2: 47 | E2: =D2/50 -> 0.94 | F2: 48.91 | G2: 17439
A3: task_01 | B3: Return Processing in Online Retail | C3: 2 | D3: 45 | E3: =D3/50 -> 0.9 | F3: 53.61 | G3: 18007
A4: task_01 | B4: Return Processing in Online Retail | C4: 3 | D4: 46.5 | E4: =D4/50 -> 0.93 | F4: 58.68 | G4: 17954
A5: task_01 | B5: Return Processing in Online Retail | C5: 4 | D5: ### | F5: 53.24 | G5: 17936 | H5: Error
A6: task_01 | B6: Return Processing in Online Retail | C6: 5 | D6: ### | F6: 51.63 | G6: 17816 | H6: Error
A7: task_01 | B7: Return Processing in Online Retail | C7: 6 | D7: ### | F7: 53.44 | G7: 17721 | H7: Error
A8: task_01 | B8: Return Processing in Online Retail | C8: 7 | D8: 46 | E8: =D8/50 -> 0.92 | F8: 56.66 | G8: 17652
A9: task_01 | B9: Return Processing in Online Retail | C9: 8 | D9: 46.5 | E9: =D9/50 -> 0.93 | F9: 55.9 | G9: 18071
A10: task_01 | B10: Return Processing in Online Retail | C10: 9 | D10: 48.5 | E10: =D10/50 -> 0.97 | F10: 55.19 | G10: 17528
A11: task_01 | B11: Return Processing in Online Retail | C11: 10 | D11: 43.5 | E11: =D11/50 -> 0.87 | F11: 61.3 | G11: 17888
A12: task_01 | B12: Return Processing in Online Retail | C12: 11 | D12: ### | F12: 61.11 | G12: 17696 | H12: Error
A13: task_01 | B13: Return Processing in Online Retail | C13: 12 | D13: 44 | E13: =D13/50 -> 0.88 | F13: 89.34 | G13: 20624
A14: task_01 | B14: Return Processing in Online Retail | C14: 13 | D14: 43 | E14: =D14/50 -> 0.86 | F14: 59.38 | G14: 17968
A15: task_01 | B15: Return Processing in Online Retail | C15: 14 | D15: 42.5 | E15: =D15/50 -> 0.85 | F15: 59.88 | G15: 17697
A16: task_01 | B16: Return Processing in Online Retail | C16: 15 | D16: 48.5 | E16: =D16/50 -> 0.97 | F16: 58.32 | G16: 18016
A17: task_01 | B17: Return Processing in Online Retail | C17: 16 | D17: ### | F17: 52.2 | G17: 17609 | H17: Error
A18: task_01 | B18: Return Processing in Online Retail | C18: 17 | D18: 44 | E18: =D18/50 -> 0.88 | F18: 57.6 | G18: 17667
A19: task_01 | B19: Return Processing in Online Retail | C19: 18 | D19: ### | F19: 53.3 | G19: 17844 | H19: Error
A20: task_01 | B20: Return Processing in Online Retail | C20: 19 | D20: 42 | E20: =D20/50 -> 0.84 | F20: 59 | G20: 17807
A21: task_01 | B21: Return Processing in Online Retail | C21: 20 | D21: 43 | E21: =D21/50 -> 0.86 | F21: 54.14 | G21: 17638
A22: task_01 | B22: Return Processing in Online Retail | C22: 21 | D22: 48.5 | E22: =D22/50 -> 0.97 | F22: 58.35 | G22: 17582
A23: task_01 | B23: Return Processing in Online Retail | C23: 22 | D23: 44.5 | E23: =D23/50 -> 0.89 | F23: 59.04 | G23: 17750
A24: task_01 | B24: Return Processing in Online Retail | C24: 23 | D24: 42 | E24: =D24/50 -> 0.84 | F24: 57.15 | G24: 17905
A25: task_01 | B25: Return Processing in Online Retail | C25: 24 | D25: ### | F25: 55.3 | G25: 17411 | H25: Error
A26: task_01 | B26: Return Processing in Online Retail | C26: 25 | D26: 43.5 | E26: =D26/50 -> 0.87 | F26: 59.31 | G26: 17855
A27: task_01 | B27: Return Processing in Online Retail | C27: 26 | D27: 45.5 | E27: =D27/50 -> 0.91 | F27: 55.75 | G27: 18030
A28: task_01 | B28: Return Processing in Online Retail | C28: 27 | D28: 50 | E28: =D28/50 -> 1 | F28: 57.99 | G28: 17705
A29: task_01 | B29: Return Processing in Online Retail | C29: 28 | D29: ### | F29: 57.88 | G29: 17597 | H29: Error
A30: task_01 | B30: Return Processing in Online Retail | C30: 29 | D30: 44.5 | E30: =D30/50 -> 0.89 | F30: 54.95 | G30: 17775
A31: task_01 | B31: Return Processing in Online Retail | C31: 30 | D31: ### | F31: 56.18 | G31: 17745 | H31: Error
A32: task_02 | B32: Insurance Claim Processing | C32: 1 | D32: 61.5 | E32: =D32/67.5 -> 0.91111111 | F32: 88.67 | G32: 21576
A33: task_02 | B33: Insurance Claim Processing | C33: 2 | D33: 57 | E33: =D33/67.5 -> 0.84444444 | F33: 75.12 | G33: 20211
A34: task_02 | B34: Insurance Claim Processing | C34: 3 | D34: ### | F34: 88.3 | G34: 21830 | H34: Error
A35: task_02 | B35: Insurance Claim Processing | C35: 4 | D35: ### | F35: 102.49 | G35: 22573 | H35: Error
A36: task_02 | B36: Insurance Claim Processing | C36: 5 | D36: ### | F36: 92.86 | G36: 21499 | H36: Error
A37: task_02 | B37: Insurance Claim Processing | C37: 6 | D37: ### | F37: 87.22 | G37: 21671 | H37: Error
A38: task_02 | B38: Insurance Claim Processing | C38: 7 | D38: ### | F38: 78.77 | G38: 20716 | H38: Error
A39: task_02 | B39: Insurance Claim Processing | C39: 8 | D39: ### | F39: 84.31 | G39: 21345 | H39: Error
A40: task_02 | B40: Insurance Claim Processing | C40: 9 | D40: 60 | E40: =D40/67.5 -> 0.88888889 | F40: 84.13 | G40: 20603
...

Sheet JSON
A1: Task ID | B1: Task Title | C1: Run # | D1: Accuracy | E1: Norm. Acc. | F1: Time (s) | G1: Tokens (OpenAI) | H1: Error
A2: task_01 | B2: Return Processing in Online Retail | C2: 1 | D2: 46 | E2: =D2/50 -> 0.92 | F2: 20.95 | G2: 8110
A3: task_01 | B3: Return Processing in Online Retail | C3: 2 | D3: 45.5 | E3: =D3/50 -> 0.91 | F3: 17.84 | G3: 7975
A4: task_01 | B4: Return Processing in Online Retail | C4: 3 | D4: 47 | E4: =D4/50 -> 0.94 | F4: 19 | G4: 7921
A5: task_01 | B5: Return Processing in Online Retail | C5: 4 | D5: 46.5 | E5: =D5/50 -> 0.93 | F5: 19.89 | G5: 8130
A6: task_01 | B6: Return Processing in Online Retail | C6: 5 | D6: 44 | E6: =D6/50 -> 0.88 | F6: 18.24 | G6: 7922
A7: task_01 | B7: Return Processing in Online Retail | C7: 6 | D7: 47.5 | E7: =D7/50 -> 0.95 | F7: 18.16 | G7: 8001
A8: task_01 | B8: Return Processing in Online Retail | C8: 7 | D8: 46 | E8: =D8/50 -> 0.92 | F8: 17.95 | G8: 7996
A9: task_01 | B9: Return Processing in Online Retail | C9: 8 | D9: 44 | E9: =D9/50 -> 0.88 | F9: 18.12 | G9: 8021
A10: task_01 | B10: Return Processing in Online Retail | C10: 9 | D10: 47 | E10: =D10/50 -> 0.94 | F10: 20.35 | G10: 8219
A11: task_01 | B11: Return Processing in Online Retail | C11: 10 | D11: 45 | E11: =D11/50 -> 0.9 | F11: 22.04 | G11: 8441
A12: task_01 | B12: Return Processing in Online Retail | C12: 11 | D12: 43.5 | E12: =D12/50 -> 0.87 | F12: 19.24 | G12: 8021
A13: task_01 | B13: Return Processing in Online Retail | C13: 12 | D13: 47 | E13: =D13/50 -> 0.94 | F13: 17.31 | G13: 7964
... A31: task_01 | B31: Return Processing in Online Retail | C31: 30 | D31: 48 | E31: =D31/50 -> 0.96 | F31: 21.77 | G31: 8109
A32: task_02 | B32: Insurance Claim Processing | C32: 1 | D32: 58 | E32: =D32/67.5 -> 0.85925926 | F32: 28.2 | G32: 9222
A33: task_02 | B33: Insurance Claim Processing | C33: 2 | D33: 62 | E33: =D33/67.5 -> 0.91851852 | F33: 26.49 | G33: 9052
A34: task_02 | B34: Insurance Claim Processing | C34: 3 | D34: 65.5 | E34: =D34/67.5 -> 0.97037037 | F34: 30.09 | G34: 9136
A35: task_02 | B35: Insurance Claim Processing | C35: 4 | D35: 63 | E35: =D35/67.5 -> 0.93333333 | F35: 27.85 | G35: 9030
A36: task_02 | B36: Insurance Claim Processing | C36: 5 | D36: 65 | E36: =D36/67.5 -> 0.96296296 | F36: 29.96 | G36: 9328
A37: task_02 | B37: Insurance Claim Processing | C37: 6 | D37: 62 | E37: =D37/67.5 -> 0.91851852 | F37: 27.98 | G37: 9073
A38: task_02 | B38: Insurance Claim Processing | C38: 7 | D38: 58 | E38: =D38/67.5 -> 0.85925926 | F38: 27.86 | G38: 9193
A39: task_02 | B39: Insurance Claim Processing | C39: 8 | D39: 65 | E39: =D39/67.5 -> 0.96296296 | F39: 28.52 | G39: 9208
A40: task_02 | B40: Insurance Claim Processing | C40: 9 | D40: 65.5 | E40: =D40/67.5 -> 0.97037037 | F40: 26.3 | G40: 8921
A41: task_02 | B41: Insurance Claim Processing | C41: 10 | D41: 58 | E41: =D41/67.5 -> 0.85925926 | F41: 28.33 | G41: 9142
A42: task_02 | B42: Insurance Claim Processing | C42: 11 | D42: 64.5 | E42: =D42/67.5 -> 0.95555556 | F42: 30.47 | G42: 9265
A43: task_02 | B43: Insurance Claim Processing | C43: 12 | D43: 63 | E43: =D43/67.5 -> 0.93333333 | F43: 29.36 | G43: 9074
... A61: task_02 | B61: Insurance Claim Processing | C61: 30 | D61: 64 | E61: =D61/67.5 -> 0.94814815 | F61: 27.68 | G61: 9048
A62: task_03 | B62: Vacation Request Process | C62: 1 | D62: ### | F62: 38.34 | G62: 10577 | H62: Error
A63: task_03 | B63: Vacation Request Process | C63: 2 | D63: ### | F63: 25.22 | G63: 8988 | H63: Error
A64: task_03 | B64: Vacation Request Process | C64: 3 | D64: ### | F64: 30.94 | G64: 9682 | H64: Error
A65: task_03 | B65: Vacation Request Process | C65: 4 | D65: ### | F65: 30.34 | G65: 9412 | H65: Error
A66: task_03 | B66: Vacation Request Process | C66: 5 | D66: 49 | E66: =D66/60 -> 0.81666667 | F66: 26.86 | G66: 8886
A67: task_03 | B67: Vacation Request Process | C67: 6 | D67: ### | F67: 24.8 | G67: 8710 | H67: Error
A68: task_03 | B68: Vacation Request Process | C68: 7 | D68: ### | F68: 30.07 | G68: 9505 | H68: Error
A69: task_03 | B69: Vacation Request Process | C69: 8 | D69: 52 | E69: =D69/60 -> 0.86666667 | F69: 34.64 | G69: 9706
A70: task_03 | B70: Vacation Request Process | C70: 9 | D70: ### | F70: 37.56 | G70: 10319 | H70: Error
A71: task_03 | B71: Vacation Request Process | C71: 10 | D71: ### | F71: 38.51 | G71: 10388 | H71: Error
A72: task_03 | B72: Vacation Request Process | C72: 11 | D72: 44.5 | E72: =D72/60 -> 0.74166667 | F72: 27.63 | G72: 9099
A73: task_03 | B73: Vacation Request Process | C73: 12 | D73: 56.5 | E73: =D73/60 -> 0.94166667 | F73: 41.16 | G73: 10508
A74: task_03 | B74: Vacation Request Process | C74: 13 | D74: ### | F74: 35.32 | G74: 10111 | H74: Error
...

Sheet LION
A1: Task ID | B1: Task Title | C1: Run # | D1: Accuracy | E1: Norm. Acc. | F1: Time (s) | G1: Tokens (OpenAI) | H1: Error
A2: task_01 | B2: Return Processing in Online Retail | C2: 1 | D2: 46 | E2: =D2/50 -> 0.92 | F2: 10.22 | G2: 7465
A3: task_01 | B3: Return Processing in Online Retail | C3: 2 | D3: 45 | E3: =D3/50 -> 0.9 | F3: 9.88 | G3: 7432
A4: task_01 | B4: Return Processing in Online Retail | C4: 3 | D4: 48 | E4: =D4/50 -> 0.96 | F4: 9.94 | G4: 7392
A5: task_01 | B5: Return Processing in Online Retail | C5: 4 | D5: 45 | E5: =D5/50 -> 0.9 | F5: 17.27 | G5: 7766
A6: task_01 | B6: Return Processing in Online Retail | C6: 5 | D6: 47.5 | E6: =D6/50 -> 0.95 | F6: 12.51 | G6: 7692
A7: task_01 | B7: Return Processing in Online Retail | C7: 6 | D7: 47.5 | E7: =D7/50 -> 0.95 | F7: 10.87 | G7: 7499
A8: task_01 | B8: Return Processing in Online Retail | C8: 7 | D8: 46 | E8: =D8/50 -> 0.92 | F8: 10.31 | G8: 7445
A9: task_01 | B9: Return Processing in Online Retail | C9: 8 | D9: 45.5 | E9: =D9/50 -> 0.91 | F9: 10.32 | G9: 7440
A10: task_01 | B10: Return Processing in Online Retail | C10: 9 | D10: 48.5 | E10: =D10/50 -> 0.97 | F10: 9.55 | G10: 7434
A11: task_01 | B11: Return Processing in Online Retail | C11: 10 | D11: 46 | E11: =D11/50 -> 0.92 | F11: 10.21 | G11: 7452
A12: task_01 | B12: Return Processing in Online Retail | C12: 11 | D12: 45.5 | E12: =D12/50 -> 0.91 | F12: 10.37 | G12: 7435
A13: task_01 | B13: Return Processing in Online Retail | C13: 12 | D13: 48 | E13: =D13/50 -> 0.96 | F13: 13.09 | G13: 7642
... A31: task_01 | B31: Return Processing in Online Retail | C31: 30 | D31: 48 | E31: =D31/50 -> 0.96 | F31: 12.05 | G31: 7526
A32: task_02 | B32: Insurance Claim Processing | C32: 1 | D32: 63 | E32: =D32/67.5 -> 0.93333333 | F32: 17.71 | G32: 8205
A33: task_02 | B33: Insurance Claim Processing | C33: 2 | D33: 61.5 | E33: =D33/67.5 -> 0.91111111 | F33: 17.11 | G33: 8096
A34: task_02 | B34: Insurance Claim Processing | C34: 3 | D34: 65.5 | E34: =D34/67.5 -> 0.97037037 | F34: 14.68 | G34: 7841
A35: task_02 | B35: Insurance Claim Processing | C35: 4 | D35: 61 | E35: =D35/67.5 -> 0.9037037 | F35: 15.78 | G35: 7964
A36: task_02 | B36: Insurance Claim Processing | C36: 5 | D36: 62 | E36: =D36/67.5 -> 0.91851852 | F36: 16.08 | G36: 8010
A37: task_02 | B37: Insurance Claim Processing | C37: 6 | D37: 66.5 | E37: =D37/67.5 -> 0.98518519 | F37: 14.37 | G37: 7889
A38: task_02 | B38: Insurance Claim Processing | C38: 7 | D38: 62.5 | E38: =D38/67.5 -> 0.92592593 | F38: 17.12 | G38: 8096
A39: task_02 | B39: Insurance Claim Processing | C39: 8 | D39: 57.5 | E39: =D39/67.5 -> 0.85185185 | F39: 16.52 | G39: 8318
A40: task_02 | B40: Insurance Claim Processing | C40: 9 | D40: 65.5 | E40: =D40/67.5 -> 0.97037037 | F40: 13.56 | G40: 7907
A41: task_02 | B41: Insurance Claim Processing | C41: 10 | D41: 62.5 | E41: =D41/67.5 -> 0.92592593 | F41: 14.54 | G41: 7945
A42: task_02 | B42: Insurance Claim Processing | C42: 11 | D42: 62 | E42: =D42/67.5 -> 0.91851852 | F42: 14.7 | G42: 8043
A43: task_02 | B43: Insurance Claim Processing | C43: 12 | D43: 64.5 | E43: =D43/67.5 -> 0.95555556 | F43: 16.99 | G43: 8302
... A61: task_02 | B61: Insurance Claim Processing | C61: 30 | D61: 66.5 | E61: =D61/67.5 -> 0.98518519 | F61: 14.48 | G61: 8036
A62: task_03 | B62: Vacation Request Process | C62: 1 | D62: 55.5 | E62: =D62/60 -> 0.925 | F62: 33.87 | G62: 8988
A63: task_03 | B63: Vacation Request Process | C63: 2 | D63: 53.5 | E63: =D63/60 -> 0.89166667 | F63: 32.74 | G63: 8905
A64: task_03 | B64: Vacation Request Process | C64: 3 | D64: 58 | E64: =D64/60 -> 0.96666667 | F64: 21.9 | G64: 8433
A65: task_03 | B65: Vacation Request Process | C65: 4 | D65: 54.5 | E65: =D65/60 -> 0.90833333 | F65: 21.14 | G65: 8209
A66: task_03 | B66: Vacation Request Process | C66: 5 | D66: 47 | E66: =D66/60 -> 0.78333333 | F66: 27.34 | G66: 8618
A67: task_03 | B67: Vacation Request Process | C67: 6 | D67: 58 | E67: =D67/60 -> 0.96666667 | F67: 26.24 | G67: 8523
A68: task_03 | B68: Vacation Request Process | C68: 7 | D68: 48.5 | E68: =D68/60 -> 0.80833333 | F68: 26.23 | G68: 8560
A69: task_03 | B69: Vacation Request Process | C69: 8 | D69: 49.5 | E69: =D69/60 -> 0.825 | F69: 32.71 | G69: 9020
A70: task_03 | B70: Vacation Request Process | C70: 9 | D70: 52 | E70: =D70/60 -> 0.86666667 | F70: 22.91 | G70: 8171
A71: task_03 | B71: Vacation Request Process | C71: 10 | D71: 56.5 | E71: =D71/60 -> 0.94166667 | F71: 19.59 | G71: 8415
A72: task_03 | B72: Vacation Request Process | C72: 11 | D72: 49 | E72: =D72/60 -> 0.81666667 | F72: 24.18 | G72: 8455
A73: task_03 | B73: Vacation Request Process | C73: 12 | D73: 56 | E73: =D73/60 -> 0.93333333 | F73: 15.19 | G73: 7943
... A78: task_03 | B78: Vacation Request Process | C78: 17 | D78: 52.5 | E78: =D78/60 -> 0.875 | F78: 22.76 | G78: 8454
...

Sheet Agentic
A1: Task ID | B1: Task Title | C1: Session ID | D1: Accuracy | E1: Norm. Acc. | F1: Time (s) | G1: Tokens (OpenAI) | H1: Error
A2: task_01 | B2: Return Processing in Online Retail | C2: 24bb7414 | D2: 48.5 | E2: =D2/50 -> 0.97 | F2: 94.78 | G2: 33112
A3: task_01 | B3: Return Processing in Online Retail | C3: 08c933d8 | D3: 48 | E3: =D3/50 -> 0.96 | F3: 107.43 | G3: 34127
A4: task_01 | B4: Return Processing in Online Retail | C4: 35921e24 | D4: 49 | E4: =D4/50 -> 0.98 | F4: 128.48 | G4: 54966
A5: task_01 | B5: Return Processing in Online Retail | C5: a69e657a | D5: 48.5 | E5: =D5/50 -> 0.97 | F5: 143.68 | G5: 65526
A6: task_01 | B6: Return Processing in Online Retail | C6: b6b3ba8c | D6: 48.5 | E6: =D6/50 -> 0.97 | F6: 131.53 | G6: 57403
A7: task_02 | B7: Insurance Claim Processing | C7: f9f48a72 | D7: 67.5 | E7: =D7/67.5 -> 1 | F7: 121.02 | G7: 54927
A8: task_02 | B8: Insurance Claim Processing | C8: 30f683ec | D8: 66.5 | E8: =D8/67.5 -> 0.98518519 | F8: 164.04 | G8: 62571
A9: task_02 | B9: Insurance Claim Processing | C9: fa49a1ec | D9: 66.5 | E9: =D9/67.5 -> 0.98518519 | F9: 155.15 | G9: 49924
A10: task_02 | B10: Insurance Claim Processing | C10: e8f5d54b | D10: 66 | E10: =D10/67.5 -> 0.97777778 | F10: 105.12 | G10: 30135
A11: task_02 | B11: Insurance Claim Processing | C11: e24d5ee8 | D11: 67 | E11: =D11/67.5 -> 0.99259259 | F11: 157.09 | G11: 60954
A12: task_03 | B12: Vacation Request Process | C12: 13709ba5 | D12: 60 | E12: =D12/60 -> 1 | F12: 148.4 | G12: 36814
A13: task_03 | B13: Vacation Request Process | C13: 2acfe0c5 | D13: 59.5 | E13: =D13/60 -> 0.99166667 | F13: 167.52 | G13: 63798
A14: task_03 | B14: Vacation Request Process | C14: c0b8d08b | D14: 59 | E14: =D14/60 -> 0.98333333 | F14: 196.92 | G14: 53579
A15: task_03 | B15: Vacation Request Process | C15: 6b0a1407 | D15: 60 | E15: =D15/60 -> 1 | F15: 250.61 | G15: 96510
A16: task_03 | B16: Vacation Request Process | C16: 57b0dd58 | D16: 59.5 | E16: =D16/60 -> 0.99166667 | F16: 104.71 | G16: 21513
A17: task_04 | B17: Processing of building permits | C17: 8499676d | D17: 70 | E17: =D17/70 -> 1 | F17: 128.22 | G17: 30024
A18: task_04 | B18: Processing of building permits | C18: 0b907f9e | D18: 67.5 | E18: =D18/70 -> 0.96428571 | F18: 170.67 | G18: 71299
A19: task_04 | B19: Processing of building permits | C19: 58fa73e7 | D19: 68 | E19: =D19/70 -> 0.97142857 | F19: 174.86 | G19: 68566
A20: task_04 | B20: Processing of building permits | C20: 186dd9ee | D20: 69.5 | E20: =D20/70 -> 0.99285714 | F20: 199.13 | G20: 72672
A21: task_04 | B21: Processing of building permits | C21: a581393e | D21: 69 | E21: =D21/70 -> 0.98571429 | F21: 190.76 | G21: 82090
A22: task_05 | B22: Office Supply Procurement | C22: 9a5ae706 | D22: 59.5 | E22: =D22/60 -> 0.99166667 | F22: 146.68 | G22: 67349
A23: task_05 | B23: Office Supply Procurement | C23: afe9c5d7 | D23: 59.5 | E23: =D23/60 -> 0.99166667 | F23: 115.63 | G23: 49184
A24: task_05 | B24: Office Supply Procurement | C24: e4ad2a47 | D24: 58.5 | E24: =D24/60 -> 0.975 | F24: 75.8 | G24: 20519
A25: task_05 | B25: Office Supply Procurement | C25: 6640ec7e | D25: 59 | E25: =D25/60 -> 0.98333333 | F25: 109 | G25: 33329
A26: task_05 | B26: Office Supply Procurement | C26: 005121f6 | D26: 59.5 | E26: =D26/60 -> 0.99166667 | F26: 157.17 | G26: 57413
